Workbook

Sheet Translators_MT_Data
A1: Covidence # | B1: Study ID_1 | C1: Study ID | D1: Title | E1: Lead author contact details | F1: Lead author affiliation | G1: Lead author affiliation country | H1: Publication date | I1: Publication Year | J1: Country in which the study was conducted | K1: Aim of study | L1: Type of study Questionnaire | M1: Type of study Focus Group | N1: Type of study Interview | O1: Type of study Other | P1: Closed Number of questions | Q1: Open Number of questions | R1: Total Number of questions | S1: Start date | T1: End date | U1: Method of dissemination | V1: Method of participation Online | W1: Method of participation Offline | X1: Study funding sources | Y1: Population description | Z1: Different population | AA1: Translation Area | AB1: Total number of participants | AC1: Detailed number of participants | AD1: Main results | AE1: Main conclusions | AF1: Key Terminology in Conclusions | AG1: Categories focused | AH1: Adoption (AD) > AD_High | AI1: Adoption (AD) > AD_Moderate | AJ1: Adoption (AD) > AD_Low | AK1: Adoption (AD) > AD_None | AL1: Attitude (ATT) > ATT_Negative | AM1: Attitude (ATT) > ATT_Positive | AN1: Ethical Concerns (EC) > EC_Bias | AO1: Ethical Concerns (EC) > EC_Copyright | AP1: Ethical Concerns (EC) > EC_Data safety & confidentiality | AQ1: Ethical Concerns (EC) > EC_Environmental sustainability | AR1: Ethical Concerns (EC) > EC_Payment | AS1: Ethical Concerns (EC) > EC_Quality | AT1: Ethical Concerns (EC) > EC_Translators’ role & status | AU1: Ethical Concerns (EC) > EC_Other | AV1: Literacy (LIT) > LIT_Generic | AW1: Literacy (LIT) > LIT_None | AX1: Literacy (LIT) > LIT_Low | AY1: Literacy (LIT) > LIT_High
A2: 76 | B2: 2CNYZQB7 | C2: Nzuanke 2018 | D2: Knowledge and Use of Computer-Assisted Translation Tools on Professional Translation in Nigeria | E2: Samson Fabian Nzuanke | F2: University of Calabar, Calabar-Nigeria | G2: Nigeria | H2: 2018/01 | I2: =LEFT(SLR_Covidence_Data_Extraction__66_files[[#This Row],[Publication date]],4) -> 2018 | J2: Nigeria | K2: To analyse the awareness level of professional Nigerian translators regarding state-of-the-art translation technologies - specifically Computer-Assisted Translation (CAT) tools like translation memory (TM), voice recognition, and term-base management. | L2: Questionnaire | S2: 2016/10 | T2: 2017/06 | U2: Social media; Professional associations networks; Other: ECOWAS Commission | V2: Online | Y2: Professional translators | Z2: Professional translators | AA2: General | AB2: 80 | AC2: 80 | AD2: 1. The Technology Usage Gap The data shows a stark contrast between "traditional" digital tools and specialized translation software: • Universal Tools: 100% of respondents use Microsoft Word and electronic dictionaries/glossaries. • Persistent Traditionalism: 60% of translators still rely on hard-copy dictionaries and pen and paper for their professional work. • Low CAT Adoption: Only 30% of translators use CAT tools generally. Specifically, only 20% use Translation Memory (TM) and only 10% use terminology management software. • Complete Absence: 0% of respondents utilized voice recognition or Optical Character Recognition (OCR) tools. 2. Awareness and Misconceptions A primary finding was that many translators do not understand the nature of the tools available to them: • The MT vs. TM Confusion: 50% of Nigerian translators mistakenly believe that Translation Memory is the same as Machine Translation (automatic translation without human aid). The researchers note this misconception directly hinders tool acquisition because translators view the tools as "not useful" or "unreliable". • Educational Shortfall: Although 70% of respondents indicated that CAT tools existed during their professional training, only 40% were actually taught how to use them in school. This suggests that academic curricula have not kept pace with the needs of the international market. 3. Benefits and User Experience For the 30% of translators who do use specialized tools, the results were largely positive: • Productivity: 25% reported that the tools helped them finish work on time. • Quality: 20% noted an increase in the consistency of terms. • Output Value: 60% of respondents felt their overall translation output had been "impressive" since the advent of these tools, indicating that the advantages outweigh the disadvantages for those who adopt them. 4. Barriers to Adoption The 70% of translators who do not use CAT tools cited several overlapping reasons for their resistance: • High Cost: 70% of non-users identified the expensive nature of the software as their primary barrier. The researchers noted that tools can cost between €60 and €695, which is often prohibitive given local income levels. • Learning Curve: 62% of non-users (and 100% of users) agreed that the time involved in learning how to use these tools is "very long". • Market Impact: 45% of respondents rated the overall impact of technology on the Nigerian industry as "discouraging," with many citing a lack of professionalism and the unorganized state of the local market. | AE2: 1. Technology is "Indispensable" but Under-Utilised The researchers conclude that while state-of-the-art tools like Translation Memory (TM) and terminology management are indispensable to the profession, they have not yet made a great impact in Nigeria. The local market remains dominated by traditional methods—specifically hard-copy dictionaries and pen and paper—even among those who use basic word processors like Microsoft Word. 2. The Triad of Barriers: Cost, Time, and Misconception The study identifies three primary reasons why Nigerian translators are discouraged from adopting new technologies: • Economic Barriers: The expensive nature of the software is the most significant hurdle; 70% of non-users cited high costs (ranging from €60 to €695) as their reason for avoidance. • The Learning Curve: There is a consensus that the time involved in learning how to use these tools is "very long," which deters busy professionals from upgrading. • Conceptual Confusion: A major conclusion is that misconceptions about the technology itself hinder its acquisition. Since 50% of translators mistakenly believe TM is the same as fully automatic machine translation, they view the tools as unreliable or not useful for high-quality work. 3. Market Alienation and Professional Risks The researchers conclude that failing to adopt these tools has direct economic consequences for Nigerian translators: • Exclusion from International Jobs: International clients and organisations increasingly demand the use of TM and terminology management tools. Translators who do not use them face a lack of jobs from the global market. • Remuneration Issues: The study suggests that if translators cannot use tools to improve their speed and satisfy international standards, they will struggle to increase their income. 4. Failure of the Educational Pipeline The study concludes that academic institutions are failing to prepare the next generation of translators for the digital age. Although most translators were trained in environments where CAT tools existed, only 10% were actually taught how to use them in school. The authors warn that if this trend continues, Nigerian translators will remain unable to compete in an "ever-changing world of technology". 5. Proven Benefits for Early Adopters Despite the general resistance, the study concludes that for the small percentage of translators who do use the tools, the results are overwhelmingly positive: • Enhanced Quality: Users reported greater consistency of terms. • Increased Productivity: Users were more likely to finish work on time. • Job Satisfaction: 60% of respondents indicated their professional output had been "impressive" since adopting the tools, proving that the advantages far outweigh the disadvantages. | AF2: • State-of-the-art translation tools: A collective term for the modern software suite, including translation memory, voice recognition, and terminology management. • Sensitising: The core action recommended by the authors to awaken Nigerian translators to the need to embrace new technologies. • Under-utilised: The primary conclusion regarding the status of specialized translation software in Nigeria. • Expensive nature: Identified as a significant discouraging factor and the main reason why 70% of non-users avoid purchasing CAT tools. • Misconception: Specifically used to describe the confusion between Translation Memory (TM) and automatic Machine Translation (MT), which leads many to believe the tools are unreliable. • Consistency of terms: A primary benefit cited by those who successfully use the tools. • Impressive: The specific term used by 60% of respondents to evaluate their professional output since the advent of these tools. • Indispensable: The researchers' final assessment of the role of technology in the profession, regardless of its current low usage in the country. • Widely demanded: Refers to the technological requirements set by international organisations and global clients, which Nigerian translators are currently struggling to meet. | AG2: Linguistic challenges; Technical aspects; Ethical aspects | AH2: =+COUNTIFS('Coded Segments'!$C$2:$C$913,SLR_Covidence_Data_Extraction__66_files[[#This Row],[Study ID_1]],'Coded Segments'!$D$2:$D$913,SLR_Covidence_Data_Extraction__66_files[[#Headers],[Adoption (AD) > AD_High]]) -> 0 | AI2: =+COUNTIFS('Coded Segments'!$C$2:$C$913,SLR_Covidence_Data_Extraction__66_files[[#This Row],[Study ID_1]],'Coded Segments'!$D$2:$D$913,SLR_Covidence_Data_Extraction__66_files[[#Headers],[Adoption (AD) > AD_Moderate]]) -> 0 | AJ2: =+COUNTIFS('Coded Segments'!$C$2:$C$913,SLR_Covidence_Data_Extraction__66_files[[#This Row],[Study ID_1]],'Coded Segments'!$D$2:$D$913,SLR_Covidence_Data_Extraction__66_files[[#Headers],[Adoption (AD) > AD_Low]]) -> 0 | AK2: =+COUNTIFS('Coded Segments'!$C$2:$C$913,SLR_Covidence_Data_Extraction__66_files[[#This Row],[Study ID_1]],'Coded Segments'!$D$2:$D$913,SLR_Covidence_Data_Extraction__66_files[[#Headers],[Adoption (AD) > AD_None]]) -> 0 | AL2: =+COUNTIFS('Coded Segments'!$C$2:$C$913,SLR_Covidence_Data_Extraction__66_files[[#This Row],[Study ID_1]],'Coded Segments'!$D$2:$D$913,SLR_Covidence_Data_Extraction__66_files[[#Headers],[Attitude (ATT) > ATT_Negative]]) -> 2 | AM2: =+COUNTIFS('Coded Segments'!$C$2:$C$913,SLR_Covidence_Data_Extraction__66_files[[#This Row],[Study ID_1]],'Coded Segments'!$D$2:$D$913,SLR_Covidence_Data_Extraction__66_files[[#Headers],[Attitude (ATT) > ATT_Positive]]) -> 1 | AN2: =+COUNTIFS('Coded Segments'!$C$2:$C$913,SLR_Covidence_Data_Extraction__66_files[[#This Row],[Study ID_1]],'Coded Segments'!$D$2:$D$913,SLR_Covidence_Data_Extraction__66_files[[#Headers],[Ethical Concerns (EC) > EC_Bias]]) -> 0 | AO2: =+COUNTIFS('Coded Segments'!$C$2:$C$913,SLR_Covidence_Data_Extraction__66_files[[#This Row],[Study ID_1]],'Coded Segments'!$D$2:$D$913,SLR_Covidence_Data_Extraction__66_files[[#Headers],[Ethical Concerns (EC) > EC_Copyright]]) -> 0 | AP2: =+COUNTIFS('Coded Segments'!$C$2:$C$913,SLR_Covidence_Data_Extraction__66_files[[#This Row],[Study ID_1]],'Coded Segments'!$D$2:$D$913,SLR_Covidence_Data_Extraction__66_files[[#Headers],[Ethical Concerns (EC) > EC_Data safety & confidentiality]]) -> 0 | AQ2: =+COUNTIFS('Coded Segments'!$C$2:$C$913,SLR_Covidence_Data_Extraction__66_files[[#This Row],[Study ID_1]],'Coded Segments'!$D$2:$D$913,SLR_Covidence_Data_Extraction__66_files[[#Headers],[Ethical Concerns (EC) > EC_Environmental sustainability]]) -> 0 | AR2: =+COUNTIFS('Coded Segments'!$C$2:$C$913,SLR_Covidence_Data_Extraction__66_files[[#This Row],[Study ID_1]],'Coded Segments'!$D$2:$D$913,SLR_Covidence_Data_Extraction__66_files[[#Headers],[Ethical Concerns (EC) > EC_Payment]]) -> 1 | AS2: =+COUNTIFS('Coded Segments'!$C$2:$C$912,SLR_Covidence_Data_Extraction__66_files[[#This Row],[Study ID_1]],'Coded Segments'!$D$2:$D$912,SLR_Covidence_Data_Extraction__66_files[[#Headers],[Ethical Concerns (EC) > EC_Quality]]) -> 1 | AT2: =+COUNTIFS('Coded Segments'!$C$2:$C$913,SLR_Covidence_Data_Extraction__66_files[[#This Row],[Study ID_1]],'Coded Segments'!$D$2:$D$913,SLR_Covidence_Data_Extraction__66_files[[#Headers],[Ethical Concerns (EC) > EC_Translators’ role & status]]) -> 0 | AU2: =+COUNTIFS('Coded Segments'!$C$2:$C$913,SLR_Covidence_Data_Extraction__66_files[[#This Row],[Study ID_1]],'Coded Segments'!$D$2:$D$913,SLR_Covidence_Data_Extraction__66_files[[#Headers],[Ethical Concerns (EC) > EC_Other]]) -> 0 | AV2: =+COUNTIFS('Coded Segments'!$C$2:$C$913,SLR_Covidence_Data_Extraction__66_files[[#This Row],[Study ID_1]],'Coded Segments'!$D$2:$D$913,SLR_Covidence_Data_Extraction__66_files[[#Headers],[Literacy (LIT) > LIT_Generic]]) -> 0 | AW2: =+COUNTIFS('Coded Segments'!$C$2:$C$913,SLR_Covidence_Data_Extraction__66_files[[#This Row],[Study ID_1]],'Coded Segments'!$D$2:$D$913,SLR_Covidence_Data_Extraction__66_files[[#Headers],[Literacy (LIT) > LIT_None ]]) -> 1 | AX2: =+COUNTIFS('Coded Segments'!$C$2:$C$913,SLR_Covidence_Data_Extraction__66_files[[#This Row],[Study ID_1]],'Coded Segments'!$D$2:$D$913,SLR_Covidence_Data_Extraction__66_files[[#Headers],[Literacy (LIT) > LIT_Low ]]) -> 2 | AY2: =+COUNTIFS('Coded Segments'!$C$2:$C$913,SLR_Covidence_Data_Extraction__66_files[[#This Row],[Study ID_1]],'Coded Segments'!$D$2:$D$913,SLR_Covidence_Data_Extraction__66_files[[#Headers],[Literacy (LIT) > LIT_High]]) -> 0
A3: 31 | B3: 2SM3ZCXD | C3: Ruffo 2018 | D3: Human-Computer Interaction in Translation: Literary Translators on Technology and Their Roles | E3: Paola Ruffo E-mail: pr25@hw.ac.uk | F3: Heriot-Watt University Edinburgh, UK | G3: UK | H3: 2018/11 | I3: =LEFT(SLR_Covidence_Data_Extraction__66_files[[#This Row],[Publication date]],4) -> 2018 | J3: UK | K3: To achieve a richer understanding of the human and technological factors at play within the field of literary translation. | L3: Questionnaire | S3: 2018 | T3: 2018 | V3: Online | X3: This doctoral research project is funded by Heriot-Watt University and is supervised by Dr Marion Winters and Prof Graham Turner, under the auspices of the Centre for Translation and Interpreting Studies in Scotland (CTISS), Heriot-Watt University, Edinburgh, Scotland, UK. | Y3: Literary translators based in Edinburgh, UK | Z3: Professional translators | AA3: Literary | AB3: 8 | AC3: 8 | AD3: 1. Technology Confidence and Usage Gap • General vs. Specific Tech: While nearly all respondents felt very confident with general technology, this confidence did not extend to translation-specific tools. • Literary vs. Non-Literary Work: Respondents reported using zero specialized translation technology (CAT or MT) for their literary projects. However, five out of the eight participants did use CAT tools for their non-literary assignments. • Preferred Tools: For literary work, translators rely on "general" technology such as Microsoft Word, online dictionaries, spellcheckers, and time management software. 2. Professional Identity and Role Perception • The "Noble" Craft: Translators view their work as a noble activity rooted in art and passion, requiring deep cultural and linguistic knowledge. • Outsider Misunderstanding: A significant finding was a sense of isolation and frustration, as participants felt that people outside the profession fail to appreciate or understand the complexity of literary translation. 3. Attitudes Toward Technology • Interpretative Flexibility: Following the SCOT framework, translators make a sharp distinction between different types of technology. • Supportive vs. Threatening Tech: ◦ Positive: Translators praised the internet, corpora, and terminology tools as essential for research. They also valued online forums and communities as a way to combat professional isolation. ◦ Negative: CAT tools and Machine Translation (MT) are largely dismissed. Respondents believe these tools will never catch on in literature as they have in other sectors because they "threaten to steal the essence" of the creative process by ignoring uniquely human aspects. | AE3: 1. The "Interpretative Flexibility" of Technology A primary conclusion is that literary translators make a sharp distinction between different categories of digital tools. Following the Social Construction of Technology (SCOT) framework, they do not view technology as a single, deterministic force but rather interpret different tools through their own professional values. • Supportive Technology: Tools that facilitate research—such as the internet, corpora, and terminology tools—are highly praised and considered essential to the modern workflow. • Threatening Technology: CAT tools and Machine Translation (MT) are largely dismissed. The conclusion is that these tools are seen as ignoring the "peculiarly human aspects" of translation and are therefore viewed as incompatible with literature. 2. Preservation of the "Noble" Professional Identity The study concludes that the rejection of specialized translation technology is deeply tied to the translator’s self-perception and professional role. • Translators view their work as a "noble activity" rooted in art, passion, and profound cultural knowledge. • Because current automation (MT/CAT) focuses on efficiency and segments, translators conclude that these tools "threaten to steal the essence" of their creative activity. • There is a strong belief that while technology has transformed other sectors, it will "never catch on" in the literary field in the same way. 3. Technology as a Solution to Isolation A significant social conclusion is that technology serves a vital role in combating the professional isolation inherent in the craft. • Translators feel that those outside the profession fail to understand the complexity of their role, leading to frustration and a sense of being undervalued. • To mitigate this, they utilize online forums and digital communities to connect with colleagues, suggesting that "social" technology is far more welcome than "productive" technology. 4. The "Non-Literary" Bridge The data suggests that the use of technology is context-dependent rather than based on a lack of skill. • Even though respondents used zero specialized technology for literary work, the majority (five out of eight) reported using CAT tools for their non-literary assignments. • This leads to the conclusion that literary translators are technologically competent but choose to reject these tools for creative work because they do not align with the artistic requirements of the genre. | AF3: • Theoretical and methodological frameworks: Refers to the underlying structures of the study, specifically the Social Construction of Technology (SCOT) and interpretivist approach. • Personal narratives: Used to describe the individual stories and qualitative data gathered from translators about their professional experiences. • Shift from humanistic to technology-driven: Describes the transition of the translation profession in the digital age, which the study aims to document through translators' own perspectives. • Perceptions of their role in society: A core metric of the study, focusing on how literary translators view their own professional identity and how they believe "outsiders" perceive them. • Attitudes towards technology: Refers to the specific feelings (often mixed) that translators hold regarding digital tools, ranging from the internet to specialized CAT and MT software. • Preliminary findings: Highlights that the data presented (specifically the rejection of specialized tech in favour of supportive tools) represents the initial pilot phase of a larger ongoing project. | AG3: Technical aspects; Ethical aspects | AH3: =+COUNTIFS('Coded Segments'!$C$2:$C$913,SLR_Covidence_Data_Extraction__66_files[[#This Row],[Study ID_1]],'Coded Segments'!$D$2:$D$913,SLR_Covidence_Data_Extraction__66_files[[#Headers],[Adoption (AD) > AD_High]]) -> 0 | AI3: =+COUNTIFS('Coded Segments'!$C$2:$C$913,SLR_Covidence_Data_Extraction__66_files[[#This Row],[Study ID_1]],'Coded Segments'!$D$2:$D$913,SLR_Covidence_Data_Extraction__66_files[[#Headers],[Adoption (AD) > AD_Moderate]]) -> 0 | AJ3: =+COUNTIFS('Coded Segments'!$C$2:$C$913,SLR_Covidence_Data_Extraction__66_files[[#This Row],[Study ID_1]],'Coded Segments'!$D$2:$D$913,SLR_Covidence_Data_Extraction__66_files[[#Headers],[Adoption (AD) > AD_Low]]) -> 0 | AK3: =+COUNTIFS('Coded Segments'!$C$2:$C$913,SLR_Covidence_Data_Extraction__66_files[[#This Row],[Study ID_1]],'Coded Segments'!$D$2:$D$913,SLR_Covidence_Data_Extraction__66_files[[#Headers],[Adoption (AD) > AD_None]]) -> 1 | AL3: =+COUNTIFS('Coded Segments'!$C$2:$C$913,SLR_Covidence_Data_Extraction__66_files[[#This Row],[Study ID_1]],'Coded Segments'!$D$2:$D$913,SLR_Covidence_Data_Extraction__66_files[[#Headers],[Attitude (ATT) > ATT_Negative]]) -> 4 | AM3: =+COUNTIFS('Coded Segments'!$C$2:$C$913,SLR_Covidence_Data_Extraction__66_files[[#This Row],[Study ID_1]],'Coded Segments'!$D$2:$D$913,SLR_Covidence_Data_Extraction__66_files[[#Headers],[Attitude (ATT) > ATT_Positive]]) -> 0 | AN3: =+COUNTIFS('Coded Segments'!$C$2:$C$913,SLR_Covidence_Data_Extraction__66_files[[#This Row],[Study ID_1]],'Coded Segments'!$D$2:$D$913,SLR_Covidence_Data_Extraction__66_files[[#Headers],[Ethical Concerns (EC) > EC_Bias]]) -> 0 | AO3: =+COUNTIFS('Coded Segments'!$C$2:$C$913,SLR_Covidence_Data_Extraction__66_files[[#This Row],[Study ID_1]],'Coded Segments'!$D$2:$D$913,SLR_Covidence_Data_Extraction__66_files[[#Headers],[Ethical Concerns (EC) > EC_Copyright]]) -> 0 | AP3: =+COUNTIFS('Coded Segments'!$C$2:$C$913,SLR_Covidence_Data_Extraction__66_files[[#This Row],[Study ID_1]],'Coded Segments'!$D$2:$D$913,SLR_Covidence_Data_Extraction__66_files[[#Headers],[Ethical Concerns (EC) > EC_Data safety & confidentiality]]) -> 0 | AQ3: =+COUNTIFS('Coded Segments'!$C$2:$C$913,SLR_Covidence_Data_Extraction__66_files[[#This Row],[Study ID_1]],'Coded Segments'!$D$2:$D$913,SLR_Covidence_Data_Extraction__66_files[[#Headers],[Ethical Concerns (EC) > EC_Environmental sustainability]]) -> 0 | AR3: =+COUNTIFS('Coded Segments'!$C$2:$C$913,SLR_Covidence_Data_Extraction__66_files[[#This Row],[Study ID_1]],'Coded Segments'!$D$2:$D$913,SLR_Covidence_Data_Extraction__66_files[[#Headers],[Ethical Concerns (EC) > EC_Payment]]) -> 0 | AS3: =+COUNTIFS('Coded Segments'!$C$2:$C$912,SLR_Covidence_Data_Extraction__66_files[[#This Row],[Study ID_1]],'Coded Segments'!$D$2:$D$912,SLR_Covidence_Data_Extraction__66_files[[#Headers],[Ethical Concerns (EC) > EC_Quality]]) -> 3 | AT3: =+COUNTIFS('Coded Segments'!$C$2:$C$913,SLR_Covidence_Data_Extraction__66_files[[#This Row],[Study ID_1]],'Coded Segments'!$D$2:$D$913,SLR_Covidence_Data_Extraction__66_files[[#Headers],[Ethical Concerns (EC) > EC_Translators’ role & status]]) -> 0 | AU3: =+COUNTIFS('Coded Segments'!$C$2:$C$913,SLR_Covidence_Data_Extraction__66_files[[#This Row],[Study ID_1]],'Coded Segments'!$D$2:$D$913,SLR_Covidence_Data_Extraction__66_files[[#Headers],[Ethical Concerns (EC) > EC_Other]]) -> 0 | AV3: =+COUNTIFS('Coded Segments'!$C$2:$C$913,SLR_Covidence_Data_Extraction__66_files[[#This Row],[Study ID_1]],'Coded Segments'!$D$2:$D$913,SLR_Covidence_Data_Extraction__66_files[[#Headers],[Literacy (LIT) > LIT_Generic]]) -> 0 | AW3: =+COUNTIFS('Coded Segments'!$C$2:$C$913,SLR_Covidence_Data_Extraction__66_files[[#This Row],[Study ID_1]],'Coded Segments'!$D$2:$D$913,SLR_Covidence_Data_Extraction__66_files[[#Headers],[Literacy (LIT) > LIT_None ]]) -> 0 | AX3: =+COUNTIFS('Coded Segments'!$C$2:$C$913,SLR_Covidence_Data_Extraction__66_files[[#This Row],[Study ID_1]],'Coded Segments'!$D$2:$D$913,SLR_Covidence_Data_Extraction__66_files[[#Headers],[Literacy (LIT) > LIT_Low ]]) -> 0 | AY3: =+COUNTIFS('Coded Segments'!$C$2:$C$913,SLR_Covidence_Data_Extraction__66_files[[#This Row],[Study ID_1]],'Coded Segments'!$D$2:$D$913,SLR_Covidence_Data_Extraction__66_files[[#Headers],[Literacy (LIT) > LIT_High]]) -> 0
A4: 13 | B4: 4VYWHYMR | C4: Vieira 2020 | D4: Automation anxiety and translators | E4: Lucas Nunes Vieira E-mail: l.nunesvieira@bristol.ac.uk | F4: School of Modern Languages, University of Bristol, UK | G4: UK | H4: 2018/11/29 | I4: =LEFT(SLR_Covidence_Data_Extraction__66_files[[#This Row],[Publication date]],4) -> 2018 | J4: Worldwide | K4: To situate translators’ discourse on machine translation and its potential economic reverberations within the context of broader work automation phenomena and empirical information on the translation profession. | O4: Other: Translators’ blog and forum postings | S4: 2017/08/11 | T4: 2017/08/13 | U4: Social media | V4: Online | Y4: Translators who publish their views online | Z4: Professional translators | AA4: General | AB4: 50 | AD4: 1. Pay Grievances are Rooted in Business Practices, Not MT A primary finding of the research is that Machine Translation (MT) is a secondary issue when translators discuss pay. • Agency Pressure: The most frequent non-descriptive grievance regarding pay was downward pressure from agencies and clients. Translators expressed frustration that agencies shape sector models to suit their own business interests, driving rates down to "para-professional" levels. • Billing Techniques: While technology does impact pay, the concern is often not with the tool itself but with how it is used for billing. Translators criticised "discount structures" where MT leverage is billed according to established repetition rates used for human-confirmed translation memories, which they deemed unreasonable. • Mixed Economic Picture: National statistics and professional surveys do not corroborate a systematic downward trend in pay. While some sectors may experience falling rates, the study notes that for many, technology's downward effect on unit rates is often compensated by an increase in volume. 2. Criticism of MT Concerns Limitations, Not Competition The study found that translators’ famously negative stance on MT is often misunderstood; most criticisms are rooted in the technology’s limitations and market consequences rather than a fear of being "replaced". • Lack of Performance Anxiety: Most translators do not believe their professional skills compete with MT, noting that MT has significant errors and low quality. One participant noted they would only worry once computers start "writing great books". • Low-Quality Exploitation: Negative attitudes are frequently directed at the low quality MT provides and how clients use it as a low-cost appeal to save money, rather than an intrinsic aversion to the technology itself. • Contextual Awareness: Translators demonstrated a sophisticated understanding of MT's limits, such as its inability to distinguish between specific terms (e.g., "journal" vs "magazine") without well-known context. 3. Nature of Professional Online Discourse The corpus analysis revealed that the majority of online discourse is actually descriptive or technical. • Knowledge Sharing: The most frequent category of comments for both "rates" and "machine translation" involved offering and obtaining help, such as sharing knowledge on how to calculate quotes or discussing technical aspects of software. • Keywords: "Rate", "software", "computer", and "technology" were the most prominent terms, indicating that economic and technological issues are similarly weighted in the professional consciousness. 4. Automation Risk and "Polanyi's Paradox" The study contextualises these results within wider economic trends, such as the polarization of jobs. • Medium-Risk Categorization: While some models estimate translation to be a "medium-risk" occupation for automation (38% probability), the study argues that translation's reliance on creative and social intelligence acts as a "bottleneck" to full automation. • Complementary Tools: In most scenarios, technology assists rather than replaces translators. Tools like SDL Trados or memoQ allow translators to recycle fragments via translation memories but leave humans in charge of abstract decision-making and editing. Ultimately, the study concludes that in the short to medium term, automation is not a danger to the profession. Instead, the real risk lies in the fragmentation of the translator's role if professionals abandon technical domains in a "mass exodus" toward more creative sectors like transcreation. | AE4: 1. Automation is not an immediate threat The researcher concludes that in the short to medium term, automation is not a danger to the translation profession. This is because technology typically replaces specific repetitive tasks rather than entire occupations—a concept known as Polanyi’s paradox. In translation, tools like MT and translation memory (TM) serve to assist rather than replace human professionals, who remain essential for abstract decision-making and creative intelligence. 2. Misunderstanding of Translators' Stance on MT A central conclusion is that translators’ famously negative attitude towards Machine Translation (MT) is frequently misunderstood. The analysis suggests that: • Most criticisms are not rooted in a fear of being outperformed by machines; translators generally believe their professional skills do not compete with low-quality MT. • Instead, hostility is directed at the technology’s limitations and the negative market consequences—such as the "low-cost appeal" that allows clients to use MT as a way to save money at the expense of quality. 3. Pay Grievances are Business-Driven The sources conclude that MT is a secondary issue in translators’ complaints regarding pay. Most economic dissatisfaction is rooted in business practices, specifically: • The downward pressure from agencies that shape the sector to suit their own business models. • The "unreasonable" billing techniques where agencies apply discount structures intended for human-confirmed TMs to MT output. • The researcher notes that national statistics do not show a systematic downward trend in pay, suggesting that for many, technology's impact on rates is compensated by an increase in work volume. 4. Warning Against Market Fragmentation The study warns against a potential "mass exodus" of qualified translators from technical domains towards more creative sectors like transcreation. The author concludes that: • Hierarchising services (viewing creative work as "superior" to technical work) may lead to a narrowing of the role of translation. • Abandoning technical sectors could lead to de-professionalisation, where tasks are left to individuals with no translation training while the core linguistic work is fragmented. 5. Recommendation for a Broadened Professional Role Ultimately, the study calls for a broadening of the translator’s role. The researcher argues that: • Translators should be viewed as comprehensive communication professionals and consultants on cultural and technological issues, rather than just linguistic transcoders. • The industry should move away from "dystopian discourses" and instead focus on open dialogue and business models that integrate the role of translators across all domains. • In any debate regarding the future of the profession, MT cannot be decoupled from its economic effects and market reverberations. | AF4: • Market reverberations and economic effects: The central conclusion that technology cannot be viewed in isolation; its impact is inextricably linked to how it affects pay and business models. • Business practices: Identified as the primary source of translators' grievances regarding pay, rather than machine translation (MT) technology itself. • Work automation phenomena: The broader context in which the study situates translation, specifically referencing the automation of middle-skilled clerical work and a shifting demand for cognitive labour. • Alternative forms of management and ownership: A proposed area for future experimentation to alleviate pressure from clients and agencies on translation rates. • Comprehensive communication professional: The recommended expanded role for translators, where they provide advice to end-clients on technology and cultural issues. • Automation resistance of creative tasks: A concept from work automation literature used to explain why creative domains are less likely to be fully automated. • De-professionalization: A warned-at consequence of an "exodus" of qualified translators from technical fields toward creative ones, which could lead to a narrowing of the concept of translation. • Dystopian discourses: The term the author uses for overly pessimistic narratives about the future of translation, which he suggests should be approached with caution. • Automation anxiety: The psychological state or industry sentiment the author seeks to address through open dialogue and the integration of translators across all domains. | AG4: Working conditions; Ethical aspects | AH4: =+COUNTIFS('Coded Segments'!$C$2:$C$913,SLR_Covidence_Data_Extraction__66_files[[#This Row],[Study ID_1]],'Coded Segments'!$D$2:$D$913,SLR_Covidence_Data_Extraction__66_files[[#Headers],[Adoption (AD) > AD_High]]) -> 0 | AI4: =+COUNTIFS('Coded Segments'!$C$2:$C$913,SLR_Covidence_Data_Extraction__66_files[[#This Row],[Study ID_1]],'Coded Segments'!$D$2:$D$913,SLR_Covidence_Data_Extraction__66_files[[#Headers],[Adoption (AD) > AD_Moderate]]) -> 0 | AJ4: =+COUNTIFS('Coded Segments'!$C$2:$C$913,SLR_Covidence_Data_Extraction__66_files[[#This Row],[Study ID_1]],'Coded Segments'!$D$2:$D$913,SLR_Covidence_Data_Extraction__66_files[[#Headers],[Adoption (AD) > AD_Low]]) -> 0 | AK4: =+COUNTIFS('Coded Segments'!$C$2:$C$913,SLR_Covidence_Data_Extraction__66_files[[#This Row],[Study ID_1]],'Coded Segments'!$D$2:$D$913,SLR_Covidence_Data_Extraction__66_files[[#Headers],[Adoption (AD) > AD_None]]) -> 0 | AL4: =+COUNTIFS('Coded Segments'!$C$2:$C$913,SLR_Covidence_Data_Extraction__66_files[[#This Row],[Study ID_1]],'Coded Segments'!$D$2:$D$913,SLR_Covidence_Data_Extraction__66_files[[#Headers],[Attitude (ATT) > ATT_Negative]]) -> 5 | AM4: =+COUNTIFS('Coded Segments'!$C$2:$C$913,SLR_Covidence_Data_Extraction__66_files[[#This Row],[Study ID_1]],'Coded Segments'!$D$2:$D$913,SLR_Covidence_Data_Extraction__66_files[[#Headers],[Attitude (ATT) > ATT_Positive]]) -> 3 | AN4: =+COUNTIFS('Coded Segments'!$C$2:$C$913,SLR_Covidence_Data_Extraction__66_files[[#This Row],[Study ID_1]],'Coded Segments'!$D$2:$D$913,SLR_Covidence_Data_Extraction__66_files[[#Headers],[Ethical Concerns (EC) > EC_Bias]]) -> 0 | AO4: =+COUNTIFS('Coded Segments'!$C$2:$C$913,SLR_Covidence_Data_Extraction__66_files[[#This Row],[Study ID_1]],'Coded Segments'!$D$2:$D$913,SLR_Covidence_Data_Extraction__66_files[[#Headers],[Ethical Concerns (EC) > EC_Copyright]]) -> 0 | AP4: =+COUNTIFS('Coded Segments'!$C$2:$C$913,SLR_Covidence_Data_Extraction__66_files[[#This Row],[Study ID_1]],'Coded Segments'!$D$2:$D$913,SLR_Covidence_Data_Extraction__66_files[[#Headers],[Ethical Concerns (EC) > EC_Data safety & confidentiality]]) -> 0 | AQ4: =+COUNTIFS('Coded Segments'!$C$2:$C$913,SLR_Covidence_Data_Extraction__66_files[[#This Row],[Study ID_1]],'Coded Segments'!$D$2:$D$913,SLR_Covidence_Data_Extraction__66_files[[#Headers],[Ethical Concerns (EC) > EC_Environmental sustainability]]) -> 0 | AR4: =+COUNTIFS('Coded Segments'!$C$2:$C$913,SLR_Covidence_Data_Extraction__66_files[[#This Row],[Study ID_1]],'Coded Segments'!$D$2:$D$913,SLR_Covidence_Data_Extraction__66_files[[#Headers],[Ethical Concerns (EC) > EC_Payment]]) -> 4 | AS4: =+COUNTIFS('Coded Segments'!$C$2:$C$912,SLR_Covidence_Data_Extraction__66_files[[#This Row],[Study ID_1]],'Coded Segments'!$D$2:$D$912,SLR_Covidence_Data_Extraction__66_files[[#Headers],[Ethical Concerns (EC) > EC_Quality]]) -> 2 | AT4: =+COUNTIFS('Coded Segments'!$C$2:$C$913,SLR_Covidence_Data_Extraction__66_files[[#This Row],[Study ID_1]],'Coded Segments'!$D$2:$D$913,SLR_Covidence_Data_Extraction__66_files[[#Headers],[Ethical Concerns (EC) > EC_Translators’ role & status]]) -> 3 | AU4: =+COUNTIFS('Coded Segments'!$C$2:$C$913,SLR_Covidence_Data_Extraction__66_files[[#This Row],[Study ID_1]],'Coded Segments'!$D$2:$D$913,SLR_Covidence_Data_Extraction__66_files[[#Headers],[Ethical Concerns (EC) > EC_Other]]) -> 0 | AV4: =+COUNTIFS('Coded Segments'!$C$2:$C$913,SLR_Covidence_Data_Extraction__66_files[[#This Row],[Study ID_1]],'Coded Segments'!$D$2:$D$913,SLR_Covidence_Data_Extraction__66_files[[#Headers],[Literacy (LIT) > LIT_Generic]]) -> 0 | AW4: =+COUNTIFS('Coded Segments'!$C$2:$C$913,SLR_Covidence_Data_Extraction__66_files[[#This Row],[Study ID_1]],'Coded Segments'!$D$2:$D$913,SLR_Covidence_Data_Extraction__66_files[[#Headers],[Literacy (LIT) > LIT_None ]]) -> 0 | AX4: =+COUNTIFS('Coded Segments'!$C$2:$C$913,SLR_Covidence_Data_Extraction__66_files[[#This Row],[Study ID_1]],'Coded Segments'!$D$2:$D$913,SLR_Covidence_Data_Extraction__66_files[[#Headers],[Literacy (LIT) > LIT_Low ]]) -> 0 | AY4: =+COUNTIFS('Coded Segments'!$C$2:$C$913,SLR_Covidence_Data_Extraction__66_files[[#This Row],[Study ID_1]],'Coded Segments'!$D$2:$D$913,SLR_Covidence_Data_Extraction__66_files[[#Headers],[Literacy (LIT) > LIT_High]]) -> 0
A5: 36 | B5: D7X889BT | C5: Fung 2018 | D5: Post-Editing in the Wild: An Empirical Study of Chinese-to-English Professional Translators in New Zealand | E5: Yuen May Fung | F5: School of Cultures, Languages and Linguistics, The University of Auckland | G5: New Zealand | H5: 2018 | I5: =LEFT(SLR_Covidence_Data_Extraction__66_files[[#This Row],[Publication date]],4) -> 2018 | J5: New Zealand | K5: • Understanding the PE Process and Product: The study seeks to describe how these translators execute a post-editing task on a technical patent text, focusing on their productivity, the quality of the final output, and the specific types of textual changes and errors made. • Correlating Perception and Actuality: It aims to examine the relationships between subjective self-reported data (such as perceived effort) and objective measured data (such as actual time spent and number of edits) to determine if specific measurements can serve as reliable proxies for post-editing effort. • Analysing the Impact of Personal Attributes: The research explores how a translator’s attitude towards machine translation (MT), their in-domain (patent) experience, and their dominant working language (L1 versus L2) impact their overall performance. | L5: Questionnaire | N5: Interviews | U5: Universities | V5: Online | W5: Offline | Y5: Professional Chinese-to-English translators | Z5: Professional translators | AA5: General | AB5: 8 | AC5: 8 | AD5: Task Execution and Productivity • Time and Efficiency: The average time taken to complete the post-editing of 332 machine-translated words was 55.7 minutes, though individual durations varied significantly from 26 to 79.6 minutes. • Productivity Levels: The group’s mean productivity was 3,256 words per day, which is higher than the industry benchmark for manual translation (2,500 words) but lower than the standard for full post-editing (5,000 words). • Workflow Distribution: Participants spent the majority of their time (71.5%) on the first post-editing pass, while 13.5% was dedicated to preparation/research and 9.8% to self-revision and review. • Editing Types: The most frequent textual changes were substitutions (45%), followed by deletions (25%), insertions (17%), and re-ordering (13%). All participants exhibited a similar distribution pattern of these edit types. Technology Adoption and Research Habits • Heavy Use of Free MT: A notable result was the frequent and conspicuous use of free online machine translation systems (such as Google Translate and Youdao fanyi) as a research tool during the task. • Online Research: Online resources accounted for over 71% of total preparation time, with online MT sites being the most used resource (46%), followed by search engines and dictionaries. Quality and Error Analysis • Error Generation: The participants introduced 107 new errors during the process, with meaning deletion being the most frequent error type (40.2%). • Overlooked Errors: The group missed 23 existing machine translation errors, the majority of which were related to accuracy (meaning) rather than fluency (grammar). • Metric Scores: All but one participant produced a final text that was an improvement over the raw MT baseline according to BLEU and TER scores. Correlations Between Effort and Actuality • Perceived vs. Actual Effort: At the sentence level, there was a weak but statistically significant correlation between how difficult a translator perceived a sentence to be and the actual time and number of edits required to fix it. • Influence of Sentence Length: Contrary to some previous studies, sentence length did not influence perceived effort ratings, meaning translators did not automatically rate longer sentences as more difficult. However, longer MT sentences did correlate with a higher number of edit events. Impact of Professional Attributes • Attitude towards MT: Translators with a more positive attitude towards technology spent more time on the first PE pass, less time on self-revision, and produced higher quality output (as indicated by lower TER scores). • In-domain Experience: Participants with prior patent translation experience were significantly more productive and made fewer accuracy-related errors than those without such experience. • The Directionality Factor: A major result was that native English speakers (L1) did not perform significantly differently from non-native English speakers (L2) in terms of productivity or overall quality. While L1 translators introduced slightly fewer fluency-related errors, this difference was not statistically significant. | AE5: Significant Individual Variation The study concludes that there is considerable variation among professional translators in terms of their post-editing style, productivity, and the quality of their final output. Despite similar professional backgrounds, individuals utilised different strategies to manage the task, with total task durations ranging from 26 to nearly 80 minutes. The Impact of Attitude and Experience A primary conclusion is that a translator's attitude toward machine translation (MT) directly influences their work. • Positive Attitude: Participants with a more favourable view of the technology tended to spend more effort improving the output and achieved significantly better quality results. • Domain Expertise: In-domain (patent) translation experience and formal translator training were concluded to be the primary drivers of higher productivity and better accuracy. The Role of Native Language (Directionality) A critical conclusion of the study is that language directionality does not significantly affect performance. The research found no empirical evidence that native English speakers (L1) performed better than non-native speakers (L2) regarding post-editing productivity or final quality. This suggests that post-editing may help "level the playing field" for translators working into their second language. Frequent Use of Free Online MT The study concludes that professional translators frequently and conspicuously use free online machine translation systems (such as Google Translate) as research and inspiration tools, even when they have no formal prior experience in post-editing. Online MT was the most used resource during task preparation, accounting for 46% of total online research time. Correlating Perception and Actuality The researcher concludes that subjective perception of effort is a reasonably valid, though weak, indicator of actual work. • Correlations: There were statistically significant correlations between how difficult a translator perceived a sentence to be and the actual time and number of edits required to fix it. • Sentence Length: Contrary to some previous theories, sentence length did not influence perceived effort, meaning translators did not view longer sentences as inherently more difficult than shorter ones. Quality Improvement and Error Generation The study concludes that while most translators produce an output that is a measurable improvement over the raw MT baseline, the process is prone to human error. Participants introduced numerous new errors (predominantly meaning deletions) and missed existing MT errors (primarily related to accuracy), highlighting that post-editing requires high levels of vigilance and specific training. Human-Machine Cooperation Ultimately, the study serves as an empirical basis for advancing the understanding of post-editing as an increasingly important form of human-machine cooperation. It concludes that as post-editing becomes a mainstream service, there is an urgent need to develop specialised training strategies, particularly for those working in their second language, to future-proof the livelihoods of professional translators. | AF5: • PE process and product: The two primary aspects of the study, covering both the actions taken during editing and the resulting translated text. • Productivity and final quality: The core metrics used to assess the commercial viability and professional success of post-editing. • Post-editor variation: A term describing the observation that translators exhibit diverse individual behaviours and styles when performing identical tasks. • Perceived, temporal, technical, and cognitive effort: The multi-dimensional framework used to measure the "work" involved in post-editing. • Acclimatisation effect: A concept suggesting that post-editors expend more effort at the beginning of a task while familiarising themselves with the text. • Fatigue effect: The negative impact on quality that occurs when participants lose concentration or tire towards the end of a translation task. • Language directionality: The distinction between translating into a native language (L1) versus a second language (L2), which the study concludes has no significant impact on post-editing performance. • Ecologically valid methods: Research approaches designed to reflect real-world scenarios and naturalistic environments rather than strictly controlled laboratory settings. • Construct validity: A research standard concerning the degree to which a test measures what it claims to measure, which the author notes can sometimes conflict with ecological validity. • Edit density indicator (EDI): A potential new metric introduced by the author to quantify the amount of editing performed on a machine-translated sentence. • Aptitude profile: A proposed diagnostic framework to help identify individuals best suited for professional post-editing roles. • Translator-computer interaction (TCI): The specific sub-field of human-technology cooperation that focuses on how translators engage with digital tools. • Cognitive translatology: An emerging area of the "scientific study of translation" that incorporates diagnostic techniques to measure brain activity and mental processes. | AG5: Linguistic challenges; Technical aspects; Training needs; Working conditions; Ethical aspects | AH5: =+COUNTIFS('Coded Segments'!$C$2:$C$913,SLR_Covidence_Data_Extraction__66_files[[#This Row],[Study ID_1]],'Coded Segments'!$D$2:$D$913,SLR_Covidence_Data_Extraction__66_files[[#Headers],[Adoption (AD) > AD_High]]) -> 0 | AI5: =+COUNTIFS('Coded Segments'!$C$2:$C$913,SLR_Covidence_Data_Extraction__66_files[[#This Row],[Study ID_1]],'Coded Segments'!$D$2:$D$913,SLR_Covidence_Data_Extraction__66_files[[#Headers],[Adoption (AD) > AD_Moderate]]) -> 2 | AJ5: =+COUNTIFS('Coded Segments'!$C$2:$C$913,SLR_Covidence_Data_Extraction__66_files[[#This Row],[Study ID_1]],'Coded Segments'!$D$2:$D$913,SLR_Covidence_Data_Extraction__66_files[[#Headers],[Adoption (AD) > AD_Low]]) -> 0 | AK5: =+COUNTIFS('Coded Segments'!$C$2:$C$913,SLR_Covidence_Data_Extraction__66_files[[#This Row],[Study ID_1]],'Coded Segments'!$D$2:$D$913,SLR_Covidence_Data_Extraction__66_files[[#Headers],[Adoption (AD) > AD_None]]) -> 0 | AL5: =+COUNTIFS('Coded Segments'!$C$2:$C$913,SLR_Covidence_Data_Extraction__66_files[[#This Row],[Study ID_1]],'Coded Segments'!$D$2:$D$913,SLR_Covidence_Data_Extraction__66_files[[#Headers],[Attitude (ATT) > ATT_Negative]]) -> 0 | AM5: =+COUNTIFS('Coded Segments'!$C$2:$C$913,SLR_Covidence_Data_Extraction__66_files[[#This Row],[Study ID_1]],'Coded Segments'!$D$2:$D$913,SLR_Covidence_Data_Extraction__66_files[[#Headers],[Attitude (ATT) > ATT_Positive]]) -> 3 | AN5: =+COUNTIFS('Coded Segments'!$C$2:$C$913,SLR_Covidence_Data_Extraction__66_files[[#This Row],[Study ID_1]],'Coded Segments'!$D$2:$D$913,SLR_Covidence_Data_Extraction__66_files[[#Headers],[Ethical Concerns (EC) > EC_Bias]]) -> 0 | AO5: =+COUNTIFS('Coded Segments'!$C$2:$C$913,SLR_Covidence_Data_Extraction__66_files[[#This Row],[Study ID_1]],'Coded Segments'!$D$2:$D$913,SLR_Covidence_Data_Extraction__66_files[[#Headers],[Ethical Concerns (EC) > EC_Copyright]]) -> 0 | AP5: =+COUNTIFS('Coded Segments'!$C$2:$C$913,SLR_Covidence_Data_Extraction__66_files[[#This Row],[Study ID_1]],'Coded Segments'!$D$2:$D$913,SLR_Covidence_Data_Extraction__66_files[[#Headers],[Ethical Concerns (EC) > EC_Data safety & confidentiality]]) -> 0 | AQ5: =+COUNTIFS('Coded Segments'!$C$2:$C$913,SLR_Covidence_Data_Extraction__66_files[[#This Row],[Study ID_1]],'Coded Segments'!$D$2:$D$913,SLR_Covidence_Data_Extraction__66_files[[#Headers],[Ethical Concerns (EC) > EC_Environmental sustainability]]) -> 0 | AR5: =+COUNTIFS('Coded Segments'!$C$2:$C$913,SLR_Covidence_Data_Extraction__66_files[[#This Row],[Study ID_1]],'Coded Segments'!$D$2:$D$913,SLR_Covidence_Data_Extraction__66_files[[#Headers],[Ethical Concerns (EC) > EC_Payment]]) -> 0 | AS5: =+COUNTIFS('Coded Segments'!$C$2:$C$912,SLR_Covidence_Data_Extraction__66_files[[#This Row],[Study ID_1]],'Coded Segments'!$D$2:$D$912,SLR_Covidence_Data_Extraction__66_files[[#Headers],[Ethical Concerns (EC) > EC_Quality]]) -> 3 | AT5: =+COUNTIFS('Coded Segments'!$C$2:$C$913,SLR_Covidence_Data_Extraction__66_files[[#This Row],[Study ID_1]],'Coded Segments'!$D$2:$D$913,SLR_Covidence_Data_Extraction__66_files[[#Headers],[Ethical Concerns (EC) > EC_Translators’ role & status]]) -> 0 | AU5: =+COUNTIFS('Coded Segments'!$C$2:$C$913,SLR_Covidence_Data_Extraction__66_files[[#This Row],[Study ID_1]],'Coded Segments'!$D$2:$D$913,SLR_Covidence_Data_Extraction__66_files[[#Headers],[Ethical Concerns (EC) > EC_Other]]) -> 0 | AV5: =+COUNTIFS('Coded Segments'!$C$2:$C$913,SLR_Covidence_Data_Extraction__66_files[[#This Row],[Study ID_1]],'Coded Segments'!$D$2:$D$913,SLR_Covidence_Data_Extraction__66_files[[#Headers],[Literacy (LIT) > LIT_Generic]]) -> 3 | AW5: =+COUNTIFS('Coded Segments'!$C$2:$C$913,SLR_Covidence_Data_Extraction__66_files[[#This Row],[Study ID_1]],'Coded Segments'!$D$2:$D$913,SLR_Covidence_Data_Extraction__66_files[[#Headers],[Literacy (LIT) > LIT_None ]]) -> 0 | AX5: =+COUNTIFS('Coded Segments'!$C$2:$C$913,SLR_Covidence_Data_Extraction__66_files[[#This Row],[Study ID_1]],'Coded Segments'!$D$2:$D$913,SLR_Covidence_Data_Extraction__66_files[[#Headers],[Literacy (LIT) > LIT_Low ]]) -> 0 | AY5: =+COUNTIFS('Coded Segments'!$C$2:$C$913,SLR_Covidence_Data_Extraction__66_files[[#This Row],[Study ID_1]],'Coded Segments'!$D$2:$D$913,SLR_Covidence_Data_Extraction__66_files[[#Headers],[Literacy (LIT) > LIT_High]]) -> 0
